<?xml version="1.0" ?>
<sdf version="1.5">


<!-- zero y inside the model is the wheel axle height -->

  <model name="podcar">
    <pose>0 0 0.3 0 0 0</pose>

    
    <!-- Main Chassis -->
    <link name="base_link">

      <!-- Physics -->
      <collision name="collision">
        <pose>0 0 0.25 0 0 0</pose>
        <geometry>
          <box>
            <size>1.6 .73 .1</size>
          </box>
        </geometry>
      </collision>      
	    <inertial>
        <mass>33.855</mass>
        <pose>-0.0856132 -0.000839955 0.238145 0 0 0</pose>
        <inertia>
          <ixx>2.2343</ixx>
          <ixy>-0.023642</ixy>
          <ixz>0.275174</ixz>
          <iyy>3.42518</iyy>
          <iyz>0.00239624</iyz>
          <izz>2.1241</izz>
        </inertia>
      </inertial>

		  <!-- only thae flat chassis above the wheels matches the physics -->
      <!-- <visual name='chassis_visual'>
        <pose>0 0 0.25 0 0 0</pose>
        <geometry>
          <box>
            <size>1.6 .73 .1</size>
          </box>
        </geometry>
        <material>
          <ambient> 0 0 0.8 0
          </ambient>
          <emissive> 0.0 0 0 0
          </emissive>
        </material>
      </visual> -->


      <!-- just to look pretty -->
      <!-- <visual name='front_canopy_visual'>
        <pose>0.25 0 0.8 0 0 0</pose>
        <geometry>
          <box>
            <size>.7 .7  1.0 </size>
          </box>
        </geometry>
        <material>
          <ambient> 0 0 0.8 0
          </ambient>
          <emissive> 0.0 0 0 0
          </emissive>
        </material>
      </visual>
      <visual name='rear_canopy_visual'>
        <pose>-0.2 0 1.0 0 0 0</pose>
        <geometry>
          <box>
            <size>.7 .7  1.5 </size>
          </box>
        </geometry>
        <material>
          <ambient> 0 0 0.8 0
          </ambient>
          <emissive> 0.0 0 0 0
          </emissive>
        </material>
      </visual> -->
      <visual name="prettyMesh">
        <pose>0 0 0  0 0 1.57079</pose>
        <geometry>
          <mesh>
            <uri>model://podcar/meshes/podcarv3.dae</uri>
            <!-- <scale>65 69 69</scale> -->
          </mesh>
        </geometry>
        <material>
          <ambient> 0 0 0.8 0
          </ambient>
          <emissive> 0.0 0 0 0
          </emissive>
        </material>
      </visual>
    </link>

    <link name="kinectLink">
      <pose>0.66 0 0  0 0 0</pose>
      <inertial>
        <mass>0.1</mass>
      </inertial>
      <collision name="collision">
        <geometry>
          <box>
            <size>0.073000 0.276000 0.072000</size>
          </box>
        </geometry>
      </collision>
      <visual name="visual">
        <geometry>
          <mesh>
            <uri>model://podcar/meshes/kinect.dae</uri>
          </mesh>
        </geometry>
      </visual>
      <sensor name="camera" type="depth">
        <update_rate>20</update_rate>
        <camera>
          <horizontal_fov>1</horizontal_fov>
          <image>
            <width>640</width>
            <height>480</height>
            <format>R8G8B8</format>
          </image>
          <clip>
            <near>0.05</near>
            <far>100</far>
          </clip>
        </camera>
        <plugin name="camera_plugin" filename="libgazebo_ros_openni_kinect.so">
          <baseline>0.2</baseline>
          <alwaysOn>true</alwaysOn>
          <!-- Keep this zero, update_rate in the parent <sensor> tag
            will control the frame rate. -->
          <updateRate>0.0</updateRate>
          <cameraName>camera</cameraName>
          <imageTopicName>/camera/rgb/image_raw</imageTopicName>
          <cameraInfoTopicName>/camera/rgb/camera_info</cameraInfoTopicName>
          <depthImageTopicName>/camera/depth/image_raw</depthImageTopicName>
          <depthImageCameraInfoTopicName>/camera/depth/camera_info</depthImageCameraInfoTopicName>
          <pointCloudTopicName>/camera/depth/points</pointCloudTopicName>
          <frameName>kinectLink</frameName>
          <pointCloudCutoff>0.05</pointCloudCutoff>
          <pointCloudCutoffMax>100</pointCloudCutoffMax>
          <distortionK1>0</distortionK1>
          <distortionK2>0</distortionK2>
          <distortionK3>0</distortionK3>
          <distortionT1>0</distortionT1>
          <distortionT2>0</distortionT2>
          <CxPrime>0</CxPrime>
          <Cx>0</Cx>
          <Cy>0</Cy>
          <focalLength>0</focalLength>
          <hackBaseline>0</hackBaseline>
        </plugin>
      </sensor>
    </link>

    <joint name="kinectJoint" type="fixed">
      <parent>base_link</parent>
      <child>kinectLink</child>
    </joint>

    <link name="back_left_wheel">
      <pose>-0.6  0.285475 0.0    0 0 0</pose>
      <inertial>
        <mass>2.6357</mass>
        <pose>0 0 0 0 0 0</pose>
        <inertia>
          <ixx>0.0246688</ixx>
          <ixy>0</ixy>
          <ixz>0</ixz>
          <iyy>0.0246688</iyy>
          <iyz>0</iyz>
          <izz>0.0441058</izz>
        </inertia>
      </inertial>
      <collision name="back_left_wheel_collision">
        <pose>0 0 0 -1.5707 0 0</pose>
        <geometry>
          <cylinder>
            <radius>0.17775</radius>
            <length>0.1143</length>
          </cylinder>
        </geometry>
        <surface>
          <friction>
            <ode>
              <mu>10</mu>
              <mu2>1</mu2>
              <slip1>0.0</slip1>
              <slip2>0.0</slip2>
            </ode>
          </friction>
        </surface>
      </collision>
      <visual name="back_left_wheel">
        <pose>0 0 0 -3.14159 0 0</pose>
        <geometry>
          <mesh>
            <uri>model://podcar/meshes/wheel.stl</uri>
          </mesh>
        </geometry>
        <material>
          <script>
            <name>Gazebo/Grey</name>
          </script>
        </material>
      </visual>
    </link>
    <joint name="back_left_joint" type="revolute">
      <parent>base_link</parent>
      <child>back_left_wheel</child>
      <axis>
        <xyz>0 1 0</xyz>
        <use_parent_model_frame>true</use_parent_model_frame>
      </axis>
      <physics>
        <ode>
          <limit>
            <cfm>0.000000</cfm>
            <erp>0.900000</erp>
          </limit>
        </ode>
      </physics>
    </joint>

    <link name="back_right_wheel">
      <pose>-0.6 -0.285475 0.0  0 0 0</pose>
      <inertial>
        <mass>2.6357</mass>
        <pose>0 0 0 0 0 0</pose>
        <inertia>
          <ixx>0.0246688</ixx>
          <ixy>0</ixy>
          <ixz>0</ixz>
          <iyy>0.0246688</iyy>
          <iyz>0</iyz>
          <izz>0.0441058</izz>
        </inertia>
      </inertial>
      <collision name="back_right_wheel_collision">
        <pose>0 0 0 -1.5707 0 0</pose>
        <geometry>
          <cylinder>
            <radius>0.17775</radius>
            <length>0.1143</length>
          </cylinder>
        </geometry>
        <surface>
          <friction>
            <ode>
              <mu>10</mu>
              <mu2>1</mu2>
              <slip1>0.0</slip1>
              <slip2>0.0</slip2>
            </ode>
          </friction>
        </surface>
      </collision>
      <visual name="back_right_wheel">
        <pose>0 0 0 -3.14159 0 0</pose>
        <geometry>
          <mesh>
            <uri>model://podcar/meshes/wheel.stl</uri>
          </mesh>
        </geometry>
        <material>
          <script>
            <name>Gazebo/Grey</name>
          </script>
        </material>
      </visual>
    </link>
    <joint name="back_right_joint" type="revolute">
      <parent>base_link</parent>
      <child>back_right_wheel</child>
      <axis>
        <xyz>0 1 0</xyz>
        <use_parent_model_frame>true</use_parent_model_frame>
        <dynamics>
          <friction>0.5</friction>
        </dynamics>
      </axis>
      <physics>
        <ode>
          <limit>
            <cfm>0.000000</cfm>
            <erp>0.900000</erp>
          </limit>
        </ode>
      </physics>
    </joint>

    <!--testing-->
    <link name="front_left_pivot">
      <pose>0.6 0.285475 0.0 0 0 0</pose>
      <inertial>
        <mass>2.6357</mass>
        <pose>0 0 0 0 0 0</pose>
        <inertia>
          <ixx>0.0246688</ixx>
          <ixy>0</ixy>
          <ixz>0</ixz>
          <iyy>0.0246688</iyy>
          <iyz>0</iyz>
          <izz>0.0441058</izz>
        </inertia>
      </inertial>
    </link>
    <joint name="front_left_pivot_joint" type="revolute">
      <parent>base_link</parent>
      <child>front_left_pivot</child>
      <axis>
        <xyz>0 0 1</xyz>
        <use_parent_model_frame>true</use_parent_model_frame>
      </axis>
      <physics>
        <ode>
          <limit>
            <cfm>0.000000</cfm>
            <erp>0.900000</erp>
          </limit>
        </ode>
      </physics>
    </joint>

    <link name="front_left_wheel">
      <pose>0.6 0.285475 0.0 0 0 0</pose>
      <inertial>
        <mass>2.6357</mass>
        <pose>0 0 0 0 0 0</pose>
        <inertia>
          <ixx>0.0246688</ixx>
          <ixy>0</ixy>
          <ixz>0</ixz>
          <iyy>0.0246688</iyy>
          <iyz>0</iyz>
          <izz>0.0441058</izz>
        </inertia>
      </inertial>
      <collision name="front_left_wheel_collision">
        <pose>0 0 0 -1.5707 0 0</pose>
        <geometry>
          <cylinder>
            <radius>0.17775</radius>
            <length>0.1143</length>
          </cylinder>
        </geometry>
        <surface>
          <friction>
            <ode>
              <mu>0.5</mu>
              <mu2>10</mu2>
              <slip1>0.01</slip1>
              <slip2>0.001</slip2>
            </ode>
          </friction>
        </surface>
      </collision>
      <visual name="front_left_wheel">
        <pose>0 0 0 -3.14159 0 0</pose>
        <geometry>
          <mesh>
            <uri>model://podcar/meshes/wheel.stl</uri>
          </mesh>
        </geometry>
        <material>
          <script>
            <name>Gazebo/Grey</name>
          </script>
        </material>
      </visual>
    </link>
    <joint name="front_left_joint" type="revolute">
      <parent>front_left_pivot</parent>
      <child>front_left_wheel</child>
      <axis>
        <xyz>0 1 0</xyz>
        <use_parent_model_frame>false</use_parent_model_frame>
      </axis>
      <physics>
        <ode>
          <limit>
            <cfm>0.000000</cfm>
            <erp>0.900000</erp>
          </limit>
        </ode>
      </physics>
    </joint>



    <!--testing-->
    <link name="front_right_pivot">
      <pose>0.6 -0.285475 0.0 0 0 0</pose>
      <inertial>
        <mass>2.6357</mass>
        <pose>0 0 0 0 0 0</pose>
        <inertia>
          <ixx>0.0246688</ixx>
          <ixy>0</ixy>
          <ixz>0</ixz>
          <iyy>0.0246688</iyy>
          <iyz>0</iyz>
          <izz>0.0441058</izz>
        </inertia>
      </inertial>
    </link>
    <joint name="front_right_pivot_joint" type="revolute">
      <parent>base_link</parent>
      <child>front_right_pivot</child>
      <axis>
        <xyz>0 0 1</xyz>
        <use_parent_model_frame>true</use_parent_model_frame>
      </axis>
      <physics>
        <ode>
          <limit>
            <cfm>0.000000</cfm>
            <erp>0.900000</erp>
          </limit>
        </ode>
      </physics>
    </joint>



    <link name="front_right_wheel">
      <pose>0.6 -0.285475 0.0 0 0 0</pose>
      <inertial>
        <mass>2.6357</mass>
        <pose>0 0 0 0 0 0</pose>
        <inertia>
          <ixx>0.0246688</ixx>
          <ixy>0</ixy>
          <ixz>0</ixz>
          <iyy>0.0246688</iyy>
          <iyz>0</iyz>
          <izz>0.0441058</izz>
        </inertia>
      </inertial>
      <collision name="front_right_wheel_collision">
        <pose>0 0 0 -1.5707 0 0</pose>
        <geometry>
          <cylinder>
            <radius>0.17775</radius>
            <length>0.1143</length>
          </cylinder>
        </geometry>
        <surface>
          <friction>
            <ode>
              <mu>0.5</mu>
              <mu2>10</mu2>
              <slip1>0.01</slip1>
              <slip2>0.001</slip2>
            </ode>
          </friction>
        </surface>
      </collision>
      <visual name="front_right_wheel">
        <pose>0 0 0 -3.14159 0 0</pose>
        <geometry>
          <mesh>
            <uri>model://podcar/meshes/wheel.stl</uri>
          </mesh>
        </geometry>
        <material>
          <script>
            <name>Gazebo/Grey</name>
          </script>
        </material>
      </visual>
    </link>
    <joint name="front_right_joint" type="revolute">
      <parent>front_right_pivot</parent>
      <child>front_right_wheel</child>
      <axis>
        <xyz>0 1 0</xyz>
        <use_parent_model_frame>false</use_parent_model_frame>
      </axis>
      <physics>
        <ode>
          <limit>
            <cfm>0.000000</cfm>
            <erp>0.900000</erp>
          </limit>
        </ode>
      </physics>
    </joint>



    <!--testing-->
    <link name="trackingrod">
      <pose>0.5 0 0.0 0 0 0</pose>
      <inertial>
        <mass>2.6357</mass>
        <pose>0 0 0 0 0 0</pose>
        <inertia>
          <ixx>0.0246688</ixx>
          <ixy>0</ixy>
          <ixz>0</ixz>
          <iyy>0.0246688</iyy>
          <iyz>0</iyz>
          <izz>0.0441058</izz>
        </inertia>
      </inertial>
      <visual name='trackingrod_visual'>
        <pose>0.0 0 0 0 0 0</pose>
        <geometry>
          <box>
            <size>0.1 .7 .1</size>
          </box>
        </geometry>
        <material>
          <ambient> 1.0 0 0.0 0
          </ambient>
          <emissive> 0.0 0 0 0
          </emissive>
        </material>
      </visual>
    </link>
    <!--<joint name="trackingrod_joint" type="fixed">
       <origin rpy="0.0 0 0" xyz="0.6 0 0"/>
       <parent link="base_link"/>
       <child link="trackingrod"/>
    </joint> -->
	  <!-- is joined at center of wheel basis origin, not at edge of wheel -->
    <joint name="tracking_right_pivot_joint" type="revolute">
      <parent>trackingrod</parent>
      <child>front_right_pivot</child>
	    <pose>-.1 0 0 0 0 0 </pose>
      <axis>
        <dynamics>
          <friction>1</friction>
        </dynamics>
        <limit>
          <lower>-0.82393858467</lower>
          <upper>0.82393858467</upper>
        </limit>
        <xyz>0 0 1</xyz>
        <use_parent_model_frame>false</use_parent_model_frame>
      </axis>
      <physics>
        <ode>
          <limit>
            <cfm>0.000000</cfm>
            <erp>0.900000</erp>
          </limit>
        </ode>
      </physics>
    </joint>
    <joint name="tracking_left_pivot_joint" type="revolute">
      <parent>trackingrod</parent>
      <child>front_left_pivot</child>
	    <pose>-.1 0 0 0 0 0 </pose>
      <axis>
        <dynamics>
          <friction>1</friction>
        </dynamics>
        <limit>
          <lower>-0.82393858467</lower>
          <upper>0.82393858467</upper>
        </limit>
        <xyz>0 0 1</xyz>
        <use_parent_model_frame>false</use_parent_model_frame>
      </axis>
      <physics>
        <ode>
          <limit>
            <cfm>0.000000</cfm>
            <erp>0.900000</erp>
          </limit>
        </ode>
      </physics>
    </joint>
    <plugin name='ackermann_drive' filename='libgazebo_ros_ackermann_drive.so'>

        <ros>
          <namespace>demo</namespace>
          <remapping>cmd_vel:=cmd_demo</remapping>
          <remapping>odom:=odom_demo</remapping>
          <remapping>distance:=distance_demo</remapping>
        </ros>

        <update_rate>100.0</update_rate>

        <!-- wheels -->
        <front_left_joint>front_left_joint</front_left_joint>
        <front_right_joint>front_right_joint</front_right_joint>
        <rear_left_joint>back_left_joint</rear_left_joint>
        <rear_right_joint>back_right_joint</rear_right_joint>
        <left_steering_joint>tracking_left_pivot_joint</left_steering_joint>
        <right_steering_joint>tracking_right_pivot_joint</right_steering_joint>
        <!--<steering_wheel_joint>steering_joint</steering_wheel_joint> -->

        <!-- Max absolute steer angle for tyre in radians-->
        <!-- Any cmd_vel angular z greater than this would be capped -->
        <max_steer>0.6458</max_steer>

        <!-- Max absolute steering angle of steering wheel -->
        <max_steering_angle>7.85</max_steering_angle>

        <!-- Max absolute linear speed in m/s -->
        <max_speed>20</max_speed>

        <!-- PID tuning -->
        <left_steering_pid_gain>1500 0 1</left_steering_pid_gain>
        <left_steering_i_range>0 0</left_steering_i_range>
        <right_steering_pid_gain>1500 0 1</right_steering_pid_gain>
        <right_steering_i_range>0 0</right_steering_i_range>
        <linear_velocity_pid_gain>1000 0 1</linear_velocity_pid_gain>
        <linear_velocity_i_range>0 0</linear_velocity_i_range>

        <!-- output -->
        <publish_odom>true</publish_odom>
        <publish_odom_tf>true</publish_odom_tf>
        <publish_wheel_tf>true</publish_wheel_tf>
        <publish_distance>true</publish_distance>

        <odometry_frame>odom_demo</odometry_frame>
        <robot_base_frame>chassis</robot_base_frame>

    </plugin>


    <!--  This plugin outputs ground truth pose, for pure ROS nodes to convert to GPS and RTK simulations.  It also receives wheel commands for gazebo physics.  
    <plugin name="libpodcarGazeboROSPlugin.so" filename="libpodcarGazeboROSPlugin.so">
      <updateRate>10.0</updateRate>
    </plugin>
    

    <plugin name="husky_diff_controller" filename="libhusky_gazebo_plugins.so">
      <alwaysOn>true</alwaysOn>
      <updateRate>100.0</updateRate>
      <backLeftJoint>back_left_joint</backLeftJoint>
      <backRightJoint>back_right_joint</backRightJoint>
      <frontLeftJoint>front_left_joint</frontLeftJoint>
      <frontRightJoint>front_right_joint</frontRightJoint>
      <wheelSeparation>0.5709</wheelSeparation>
      <wheelDiameter>0.3555</wheelDiameter>
      <torque>35</torque>
    </plugin> -->


  </model>
</sdf>
