<?xml version="1.0" ?>
<!-- =================================================================================== -->
<!-- |    This document was autogenerated by xacro from podcar.urdf.xacro              | -->
<!-- |    EDITING THIS FILE BY HAND IS NOT RECOMMENDED                                 | -->
<!-- =================================================================================== -->
<robot name="podcar" xmlns:xacro="http://www.ros.org/wiki/xacro">
  <!--<origin xyz="0 0 0.3" rpy="0 0 0"/> -->
  <!-- <link name="base_footprint"/>
  
  <joint name="chassis_joint" type="fixed">
    <origin xyz="0 0 0.238145" rpy="0 0 0" />
    <parent link="base_footprint" />
    <child link="base_link" />
  </joint> -->

  <link name="base_link">
    <inertial>
      <mass value="1.14395"/>
      <origin rpy=" 0 0 0" xyz="0 0 0.25"/>
      <inertia ixx="0.126164" ixy="0.0" ixz="0.0" iyy="0.416519" iyz="0.0" izz="0.481014"/>
    </inertial>
    <collision>
      <origin rpy=" 0 0 0" xyz="0 0 0.25"/>
      <geometry>
        <box size="1.6 0.73 0.1"/>
      </geometry>
    </collision>
    <visual>
      <origin rpy="0 0 0" xyz="0 0 0.25"/>
      <geometry>
        <mesh filename="file://$(find pod2_description)/meshes/podcarv3.dae" scale="1 1 1"/>
        <!-- <scale>65 69 69</scale> -->
      </geometry>
    </visual>
  </link>
 
  <gazebo reference="base_link">
    <dampingFactor>1</dampingFactor>
  </gazebo>
  <gazebo reference="front_left_wheel">
    <mu1 value="0.5"/>
    <mu2 value="1.0"/>
    <!-- <slip1 value="0.01"/>
    <slip2 value="0.001"/> -->
    <fdir1>0 0 1</fdir1>
    <material>Gazebo/Black</material>
  </gazebo>
  <gazebo reference="front_right_wheel">
    <mu1 value="0.5"/>
    <mu2 value="1.0"/>
    <fdir1>0 0 1</fdir1>
    <!-- <slip1 value="0.01"/>
    <slip2 value="0.001"/> -->
    <material>Gazebo/Black</material>
  </gazebo>
  <gazebo reference="back_left_wheel">
    <mu1 value="0.5"/>
    <mu2 value="1.0"/>
    <fdir1>0 0 1</fdir1>
    <!-- <slip1 value="0.0"/>
    <slip2 value="0.0"/> -->
    <material>Gazebo/Black</material>
  </gazebo>
  <gazebo reference="back_right_wheel">
    <mu1 value="10"/>
    <mu2 value="1"/>
    <fdir1>0 0 1</fdir1>
    <!-- <slip1 value="0.0"/>
    <slip2 value="0.0"/> -->
    <material>Gazebo/Black</material>
  </gazebo>

  <link name="front_left_wheel">
    <origin xyz="0.6 0.285475 0.0" rpy="-1.5707 0 0"/>
    <inertial>
      <mass value="2.0"/>
      <origin xyz="0 0 0"/>
      <inertia ixx="0.145833" ixy="0.0" ixz="0.0" iyy="0.145833" iyz="0.0" izz="0.125"/>
    </inertial>
    <collision>
      <!-- <origin xyz="0 0 0" rpy="-1.5707 0 0"/> -->
      <geometry>
        <cylinder length="0.15" radius="0.3"/>
      </geometry>
    </collision>
    <visual>
      <!-- <origin xyz="0 0 0" rpy="-3.14159 0 0"/> -->
      <geometry>
        <mesh filename="file://$(find pod2_description)/meshes/wheel.stl"/>
      </geometry>
    </visual>
  </link>

  
  <link name="front_right_wheel">
    <origin xyz="0.6 -0.285475 0.0" rpy="-1.5707 0 0"/>
    <inertial>
      <mass value="2.0"/>
      <origin xyz="0 0 0"/>
      <inertia ixx="0.145833" ixy="0.0" ixz="0.0" iyy="0.145833" iyz="0.0" izz="0.125"/>
    </inertial>
    <collision >
      <!-- <origin xyz="0 0 0" rpy="-1.5707 0 0"/> -->
      <geometry>
        <cylinder length="0.15" radius="0.3"/>
      </geometry>
    </collision>
    <visual>
      <!-- <origin xyz="0 0 0" rpy="-3.14159 0 0"/> -->
      <geometry>
        <mesh filename="file://$(find pod2_description)/meshes/wheel.stl"/>
      </geometry> 
    </visual>
  </link>
  <link name="back_left_wheel">
    <origin xyz="-0.6 0.285475 0.0" rpy="-1.5707 0 0"/> 
    <inertial>
      <mass value="2.0"/>
      <origin xyz="0 0 0"/>
      <inertia ixx="0.145833" ixy="0.0" ixz="0.0" iyy="0.145833" iyz="0.0" izz="0.125"/>
    </inertial>
    <collision>
      <!-- <origin xyz="0 0 0" rpy="-1.5707 0 0"/> -->
      <geometry>
        <cylinder length="0.15" radius="0.3"/>
      </geometry>
    </collision>
    <visual>
      <!-- <origin xyz="0 0 0" rpy="-3.14159 0 0"/> -->
      <geometry>
        <mesh filename="file://$(find pod2_description)/meshes/wheel.stl"/>
      </geometry> 
    </visual>
  </link>
  <link name="back_right_wheel">
    <origin xyz="-0.6 -0.285475 0.0" rpy="-1.5707 0 0"/>
    <inertial>
      <mass value="2.0"/>
      <origin xyz="0 0 0" rpy="0 0 0"/>
      <inertia ixx="0.145833" ixy="0.0" ixz="0.0" iyy="0.145833" iyz="0.0" izz="0.125"/>
    </inertial>
    <collision>
      <!-- <origin xyz="0 0 0" rpy="-1.5707 0 0"/> -->
      <geometry>
        <cylinder length="0.15" radius="0.3"/>
      </geometry>
    </collision>
    <visual>
      <!-- <origin xyz="0 0 0" rpy="-3.14159 0 0"/> -->
      <geometry>
        <mesh filename="file://$(find pod2_description)/meshes/wheel.stl"/>
      </geometry> 
    </visual>
  </link>
  <!--Pivot links of the wheels with tracking rod as the parent link --> 
  <link name="front_left_wheel_steer">
    <origin xyz="0.6 0.285475 0.0" rpy="0 0 0"/>
    <inertial>
      <mass value="0.5"/>
      <origin xyz="0 0 0"/>
      <inertia ixx="0.0153" iyy="0.025" izz="0.0153"
               ixy="0" ixz="0" iyz="0"/>
    </inertial>
    <visual>
      <origin xyz ="0 0 0" rpy="0 0 0"/>
      <geometry>
        <cylinder length="0.01" radius="0.01"/>
      </geometry>
      <material name="black">
        <color rgba="0 0 0 1"/>
      </material>
    </visual>
    <collision>
      <geometry>
        <cylinder length="0.01" radius="0.01"/>
      </geometry>
    </collision>
  </link>
  <link name="front_right_wheel_steer">
    <origin xyz="0.6 -0.285475 0.0" rpy="0 0 0"/>
    <inertial>
      <mass value="0.5"/>
      <origin xyz="0 0 0"/>
      <inertia ixx="0.0153" iyy="0.025" izz="0.0153"
               ixy="0" ixz="0" iyz="0"/>
    </inertial>
    <visual>
      <geometry>
        <cylinder length="0.01" radius="0.01"/>
      </geometry>
      <material name="black">
        <color rgba="0 0 0 1"/>
      </material>
    </visual>
    <collision>
      <geometry>
        <cylinder length="0.01" radius="0.01"/>
      </geometry>
    </collision>
  </link>

  <joint name="back_left_wheel_joint" type="revolute">
    <origin rpy="-3.14 0 0" xyz="-0.6 0.285475 -0.045" />
    <parent link="base_link" />
    <child link="back_left_wheel" />
    <axis xyz="0 0 1" />
    <dynamics damping="0.0" friction="1"/>
    <limit effort="25" lower="-0.82393858467" upper="0.82393858467" velocity="1.0"/>
  </joint>
 

  <joint name="back_right_wheel_joint" type="revolute">
    <origin rpy="-3.14 0 0" xyz="-0.6 -0.285475 -0.045" />
    <parent link="base_link" />
    <child link="back_right_wheel" />
    <axis xyz="0 0 1" />
    <dynamics damping="0.0" friction="1"/>
    <limit effort="25" lower="-0.82393858467" upper="0.82393858467" velocity="1.0"/>
  </joint>

  <joint name="front_left_wheel_steer_joint" type="revolute">
   <origin rpy="0 0 0" xyz="0.6 0.285475 -0.045"/>
    <parent link="base_link" />
    <child link="front_left_wheel_steer" />
    <axis xyz="0 0 1" />
    <!-- <dynamics damping="0.0" friction="1"/> -->
    <limit effort="25" lower="-0.82393858467" upper="0.82393858467" velocity="1.0"/>
  </joint>
  <joint name="front_left_wheel_joint" type="revolute">
    <axis xyz="0 0 1"/>
    <parent link="front_left_wheel_steer"/>
    <child link="front_left_wheel"/>
    <origin rpy="-3.14 0 0" xyz="0 0 0"/>
    <dynamics damping="0.0" friction="1"/>
    <limit effort="10" lower="-0.82393858467" upper="0.82393858467" velocity="1.0"/>
  </joint>
  <joint name="front_right_wheel_steer_joint" type="revolute">
   <origin rpy="0 0 0" xyz="0.6 -0.285475 -0.045"/>
    <parent link="base_link" />
    <child link="front_right_wheel_steer" />
    <axis xyz="0 0 1" />
    <!-- <dynamics damping="0.0" friction="1"/> -->
    <limit effort="25" lower="-0.82393858467" upper="0.82393858467" velocity="1.0"/>
  </joint>
  <joint name="front_right_wheel_joint" type="revolute">
    <axis xyz="0 0 1"/>
    <parent link="front_right_wheel_steer"/>
    <child link="front_right_wheel"/>
    <origin rpy="-3.14 0 0" xyz="0 0 0"/>
    <dynamics damping="0.0" friction="1"/>
    <limit effort="10" lower="-0.82393858467" upper="0.82393858467" velocity="1.0"/>
  </joint>

  <!-- Adding velodyne VLP-16 sensor -->
  <joint name="velodyne_base_mount_joint" type="fixed">
    <origin rpy="0 0 0" xyz="-0.34 0 1.75"/>
    <parent link="base_link"/>
    <child link="velodyne_base_link"/>
  </joint>
  <link name="velodyne_base_link">
    <inertial>
      <mass value="0.2"/>
      <origin xyz="-0.34 0.26 1.75"/>
      <inertia ixx="0.000908059425" ixy="0" ixz="0" iyy="0.000908059425" iyz="0" izz="0.0011049624"/>
    </inertial>
    <visual>
      <geometry>
        <mesh filename="file://$(find pod2_description)/meshes/VLP16_base_1.dae"/>
      </geometry>
    </visual>
    <collision>
      <origin rpy="0 0 0" xyz="0 0 0.03"/>
      <geometry>
        <cylinder length="0.0717" radius="0.0516"/>
      </geometry>
    </collision>
  </link>
  <joint name="velodyne_base_scan_joint" type="fixed">
    <origin rpy="0 0 0" xyz="0 0 0.03"/>
    <parent link="velodyne_base_link"/>
    <child link="velodyne"/>
  </joint>
  <link name="velodyne">
    <inertial>
      <mass value="0.01"/>
      <origin xyz="0 0 0.03"/>
      <inertia ixx="1e-7" ixy="0" ixz="0" iyy="1e-7" iyz="0" izz="1e-7"/>
    </inertial>
    <visual>
      <origin xyz="0 0 0.03"/>
      <geometry>
        <mesh filename="file://$(find pod2_description)/meshes/VLP16_scan.dae"/>
      </geometry>
    </visual>
  </link> 
  <gazebo reference="velodyne">
    <sensor name="gpu_lidar" type="gpu_lidar">
      <pose>0 0 0 0 0 0</pose>
      <topic>lidar</topic>
      <visualize>false</visualize>
      <update_rate>10</update_rate>
      <ray>
        <scan>
          <horizontal>
            <samples>1</samples>
            <resolution>1</resolution>
            <min_angle>0</min_angle>
            <max_angle>0</max_angle>
          </horizontal>
          <vertical>
            <samples>1</samples>
            <resolution>1</resolution>
            <min_angle>0</min_angle>
            <max_angle>0</max_angle>
          </vertical>
        </scan>
        <range>
          <min>0.3</min>
          <max>131.0</max>
          <resolution>0.001</resolution>
        </range>
      </ray>
      <plugin filename="gz-sim-sensors-system" name="gz::sim::systems::Sensors">
        <render_engine>ogre2</render_engine>
      </plugin>
    </sensor>
  </gazebo> 
  <gazebo>
    <plugin
      filename="gz-sim-ackermann-steering-system"
      name="gz::sim::systems::AckermannSteering">
      <left_joint>front_left_wheel_joint</left_joint>
      <left_joint>rear_left_wheel_joint</left_joint>
      <right_joint>front_right_wheel_joint</right_joint>
      <right_joint>rear_right_wheel_joint</right_joint>
      <left_steering_joint>front_left_wheel_steer_joint</left_steering_joint>
      <right_steering_joint>front_right_wheel_steer_joint</right_steering_joint>
      <kingpin_width>1.0</kingpin_width>
      <steering_limit>0.5</steering_limit>
      <wheel_base>2.5</wheel_base>
      <wheel_separation>1.5</wheel_separation>
      <wheel_radius>0.17775</wheel_radius>
      <min_velocity>-0.5</min_velocity>
      <max_velocity>0.5</max_velocity>
      <min_acceleration>-1</min_acceleration>
      <max_acceleration>1</max_acceleration>
    </plugin>
  </gazebo>
  <!--<gazebo>
    <plugin filename="libgazebo_ros_joint_state_publisher.so" name="gazebo_joint_state_publisher">
      <robotNamespace>/podcar</robotNamespace>   
      <joint_name>back_left_wheel_joint</joint_name>     
      <joint_name>back_right_wheel_joint</joint_name>
      <joint_name>front_left_wheel_steer_joint</joint_name> 
      <joint_name>front_left_wheel_joint</joint_name>
      <joint_name>front_right_wheel_steer_joint</joint_name>
      <joint_name>front_right_wheel_joint</joint_name>
     
      <updateRate>100.0</updateRate>
      <alwaysOn>true</alwaysOn>
    </plugin>
  </gazebo> -->
</robot>
