<sdf version='1.7'>
  <model name='podcar'>
    <link name='base_link'>
      <inertial>
        <mass>33.855</mass>
        <pose>-0.0856132 -0.000839955 0.238145 0 0 0</pose>
        <inertia>
          <ixx>2.2343</ixx>
          <ixy>-0.023642</ixy>
          <ixz>0.275174</ixz>
          <iyy>3.42518</iyy>
          <iyz>0.00239624</iyz>
          <izz>2.1241</izz>
        </inertia>
      </inertial>
      <collision name='base_link_collision'>
        <pose>0 0 0.25 0 -0 0</pose>
        <geometry>
          <box>
            <size>1.6 0.73 0.1</size>
          </box>
        </geometry>
      </collision>
      <collision name='base_link_fixed_joint_lump__velodyne_base_link_collision_1'>
        <pose>-0.34 0 1.78 0 -0 0</pose>
        <geometry>
          <cylinder>
            <length>0.0717</length>
            <radius>0.0516</radius>
          </cylinder>
        </geometry>
      </collision>
      <visual name='base_link_visual'>
        <pose>0 0 0 0 -0 1.57079</pose>
        <geometry>
          <mesh>
            <scale>1 1 1</scale>
            <uri>file://$(find pod2_description)/meshes/podcarv3.dae</uri>
          </mesh>
        </geometry>
      </visual>
      <visual name='base_link_fixed_joint_lump__velodyne_base_link_visual_1'>
        <pose>-0.34 0 1.75 0 -0 0</pose>
        <geometry>
          <mesh>
            <scale>1 1 1</scale>
            <uri>file://$(find pod2_description)/meshes/VLP16_base_1.dae</uri>
          </mesh>
        </geometry>
      </visual>
      <visual name='base_link_fixed_joint_lump__velodyne_visual_2'>
        <pose>-0.34 0 1.81 0 -0 0</pose>
        <geometry>
          <mesh>
            <scale>1 1 1</scale>
            <uri>file://$(find pod2_description)/meshes/VLP16_scan.dae</uri>
          </mesh>
        </geometry>
      </visual>
      <sensor name='lidar_sensor' type='ray'>
        <visualize>0</visualize>
        <update_rate>10</update_rate>
        <ray>
          <scan>
            <horizontal>
              <samples>1875</samples>
              <resolution>1</resolution>
              <min_angle>-3.14159</min_angle>
              <max_angle>3.14159</max_angle>
            </horizontal>
            <vertical>
              <samples>16</samples>
              <resolution>1</resolution>
              <min_angle>-0.261799</min_angle>
              <max_angle>0.261799</max_angle>
            </vertical>
          </scan>
          <range>
            <min>0.3</min>
            <max>131</max>
            <resolution>0.001</resolution>
          </range>
          <noise>
            <type>gaussian</type>
            <mean>0</mean>
            <stddev>0</stddev>
          </noise>
        </ray>
        <plugin name='gazebo_ros_laser' filename='libgazebo_ros_laser.so'>
          <topicName>/points_raw</topicName>
          <frameName>velodyne</frameName>
          <min_range>0.9</min_range>
          <max_range>130.0</max_range>
          <gaussianNoise>0.008</gaussianNoise>
        </plugin>
        <pose>-0.34 0 1.78 0 -0 0</pose>
      </sensor>
    </link>
    <joint name='back_left_wheel_joint' type='revolute'>
      <pose relative_to='base_link'>-0.6 0.4 0 0 -0 0</pose>
      <parent>base_link</parent>
      <child>back_left_wheel</child>
      <axis>
        <xyz>0 1 0</xyz>
        <use_parent_model_frame>true</use_parent_model_frame>
      </axis>
      <physics>
        <ode>
          <limit>
            <cfm>0.000000</cfm>
            <erp>0.900000</erp>
          </limit>
        </ode>
      </physics>
    </joint>
    <link name='back_left_wheel'>
      <pose relative_to='back_left_wheel_joint'>0 0 0 0 -0 0</pose>
      <inertial>
        <pose>0 0 0 0 -0 0</pose>
        <mass>2.6357</mass>
        <inertia>
          <ixx>0.0246688</ixx>
          <ixy>0</ixy>
          <ixz>0</ixz>
          <iyy>0.0246688</iyy>
          <iyz>0</iyz>
          <izz>0.0441058</izz>
        </inertia>
      </inertial>
      <collision name='back_left_wheel_collision_collision'>
        <pose>0 0 0 -1.5707 0 0</pose>
        <geometry>
          <cylinder>
            <length>0.1143</length>
            <radius>0.17775</radius>
          </cylinder>
        </geometry>
        <surface>
          <contact>
            <ode/>
          </contact>
          <friction>
            <ode>
              <mu>10</mu>
              <mu2>1</mu2>
            </ode>
          </friction>
        </surface>
      </collision>
      <visual name='back_left_wheel_visual'>
        <pose>0 0 0 -3.14159 0 0</pose>
        <geometry>
          <mesh>
            <scale>1 1 1</scale>
            <uri>file://$(find pod2_description)/meshes/wheel.stl</uri>
          </mesh>
        </geometry>
        <material>
          <script>
            <name>Gazebo/Black</name>
            <uri>file://media/materials/scripts/gazebo.material</uri>
          </script>
        </material>
      </visual>
      <slip1 value='0.0'/>
      <slip2 value='0.0'/>
    </link>
    <joint name='back_right_wheel_joint' type='revolute'>
      <pose relative_to='base_link'>-0.6 -0.4 0 0 -0 0</pose>
      <parent>base_link</parent>
      <child>back_right_wheel</child>
      <axis>
        <xyz>0 1 0</xyz>
        <dynamics>
          <damping>0</damping>
          <friction>0.5</friction>
        </dynamics>
      </axis>
       <physics>
        <ode>
          <limit>
            <cfm>0.000000</cfm>
            <erp>0.900000</erp>
          </limit>
        </ode>
      </physics>
    </joint>
    </joint>
    <link name='back_right_wheel'>
      <pose relative_to='back_right_wheel_joint'>0 0 0 0 -0 0</pose>
      <inertial>
        <pose>0 0 0 0 -0 0</pose>
        <mass>2.6357</mass>
        <inertia>
          <ixx>0.0246688</ixx>
          <ixy>0</ixy>
          <ixz>0</ixz>
          <iyy>0.0246688</iyy>
          <iyz>0</iyz>
          <izz>0.0441058</izz>
        </inertia>
      </inertial>
      <collision name='back_right_wheel_collision_collision'>
        <pose>0 0 0 -1.5707 0 0</pose>
        <geometry>
          <cylinder>
            <length>0.1143</length>
            <radius>0.17775</radius>
          </cylinder>
        </geometry>
        <surface>
          <contact>
            <ode/>
          </contact>
          <friction>
            <ode>
              <mu>10</mu>
              <mu2>1</mu2>
            </ode>
          </friction>
        </surface>
      </collision>
      <visual name='back_right_wheel_visual'>
        <pose>0 0 0 -3.14159 0 0</pose>
        <geometry>
          <mesh>
            <scale>1 1 1</scale>
            <uri>file://$(find pod2_description)/meshes/wheel.stl</uri>
          </mesh>
        </geometry>
        <material>
          <script>
            <name>Gazebo/Black</name>
            <uri>file://media/materials/scripts/gazebo.material</uri>
          </script>
        </material>
      </visual>
      <slip1 value='0.0'/>
      <slip2 value='0.0'/>
    </link>
    <joint name='trackingrod_joint' type='revolute'>
      <pose relative_to='base_link'>0.6 0 0 0 -0 0</pose>
      <parent>base_link</parent>
      <child>trackingrod</child>
      <axis>
        <xyz>1 0 0</xyz>
        <limit>
          <lower>-0.823939</lower>
          <upper>0.823939</upper>
          <effort>10000</effort>
          <velocity>30</velocity>
        </limit>
        <dynamics>
          <spring_reference>0</spring_reference>
          <spring_stiffness>0</spring_stiffness>
        </dynamics>
      </axis>
    </joint>
    <link name='trackingrod'>
      <pose relative_to='trackingrod_joint'>0 0 0 0 -0 0</pose>
      <inertial>
        <pose>0 0 0 0 -0 0</pose>
        <mass>2.6357</mass>
        <inertia>
          <ixx>0.0246688</ixx>
          <ixy>0</ixy>
          <ixz>0</ixz>
          <iyy>0.0246688</iyy>
          <iyz>0</iyz>
          <izz>0.0441058</izz>
        </inertia>
      </inertial>
      <visual name='trackingrod_visual_visual'>
        <pose>0 0 0 0 -0 0</pose>
        <geometry>
          <box>
            <size>0.1 0.7 0.1</size>
          </box>
        </geometry>
      </visual>
    </link>
    <joint name='tracking_left_pivot_joint' type='revolute'>
      <pose relative_to='trackingrod'>0 0.4 0 0 -0 0</pose>
      <parent>trackingrod</parent>
      <child>front_left_pivot</child>
      <axis>
        <xyz>0 0 1</xyz>
        <limit>
          <lower>-0.823939</lower>
          <upper>0.823939</upper>
          <effort>10000</effort>
          <velocity>30</velocity>
        </limit>
        <dynamics>
          <damping>0</damping>
          <friction>1</friction>
          <spring_reference>0</spring_reference>
          <spring_stiffness>0</spring_stiffness>
        </dynamics>
      </axis>
    </joint>
    <link name='front_left_pivot'>
      <pose relative_to='tracking_left_pivot_joint'>0 0 0 0 -0 0</pose>
      <inertial>
        <pose>0 0 0 0 -0 0</pose>
        <mass>2.6357</mass>
        <inertia>
          <ixx>0.0246688</ixx>
          <ixy>0</ixy>
          <ixz>0</ixz>
          <iyy>0.0246688</iyy>
          <iyz>0</iyz>
          <izz>0.0441058</izz>
        </inertia>
      </inertial>
    </link>
    <joint name='front_left_wheel_joint' type='revolute'>
      <pose relative_to='front_left_pivot'>0 0 0 0 -0 0</pose>
      <parent>front_left_pivot</parent>
      <child>front_left_wheel</child>
      <axis>
        <dynamics>
          <friction>1</friction>
        </dynamics>
        <limit>
          <lower>-0.82393858467</lower>
          <upper>0.82393858467</upper>
        </limit>
        <xyz>0 0 1</xyz>
        
      </axis>
      <physics>
        <ode>
          <limit>
            <cfm>0.000000</cfm>
            <erp>0.900000</erp>
          </limit>
        </ode>
      </physics>
    </joint>

    <link name='front_left_wheel'>
      <pose relative_to='front_left_wheel_joint'>0 0 0 0 -0 0</pose>
      <inertial>
        <pose>0 0 0 0 -0 0</pose>
        <mass>2.6357</mass>
        <inertia>
          <ixx>0.0246688</ixx>
          <ixy>0</ixy>
          <ixz>0</ixz>
          <iyy>0.0246688</iyy>
          <iyz>0</iyz>
          <izz>0.0441058</izz>
        </inertia>
      </inertial>
      <collision name='front_left_wheel_collision_collision'>
        <pose>0 0 0 -1.5707 0 0</pose>
        <geometry>
          <cylinder>
            <length>0.1143</length>
            <radius>0.17775</radius>
          </cylinder>
        </geometry>
        <surface>
          <contact>
            <ode/>
          </contact>
          <friction>
            <ode>
              <mu>0.5</mu>
              <mu2>10</mu2>
            </ode>
          </friction>
        </surface>
      </collision>
      <visual name='front_left_wheel_visual'>
        <pose>0 0 0 -3.14159 0 0</pose>
        <geometry>
          <mesh>
            <scale>1 1 1</scale>
            <uri>file://$(find pod2_description)/meshes/wheel.stl</uri>
          </mesh>
        </geometry>
        <material>
          <script>
            <name>Gazebo/Black</name>
            <uri>file://media/materials/scripts/gazebo.material</uri>
          </script>
        </material>
      </visual>
      <slip1 value='0.01'/>
      <slip2 value='0.001'/>
    </link>
    <joint name='tracking_right_pivot_joint' type='revolute'>
      <pose relative_to='trackingrod'>0 -0.4 0 0 -0 0</pose>
      <parent>trackingrod</parent>
      <child>front_right_pivot</child>
      <axis>
        <dynamics>
          <friction>1</friction>
        </dynamics>
        <limit>
          <lower>-0.82393858467</lower>
          <upper>0.82393858467</upper>
        </limit>
        <xyz>0 0 1</xyz>
      </axis>
      <physics>
        <ode>
          <limit>
            <cfm>0.000000</cfm>
            <erp>0.900000</erp>
          </limit>
        </ode>
      </physics>
    </joint>
    <link name='front_right_pivot'>
      <pose relative_to='tracking_right_pivot_joint'>0 0 0 0 -0 0</pose>
      <inertial>
        <pose>0 0 0 0 -0 0</pose>
        <mass>2.6357</mass>
        <inertia>
          <ixx>0.0246688</ixx>
          <ixy>0</ixy>
          <ixz>0</ixz>
          <iyy>0.0246688</iyy>
          <iyz>0</iyz>
          <izz>0.0441058</izz>
        </inertia>
      </inertial>
    </link>
    <joint name='front_right_wheel_joint' type='revolute'>
      <pose relative_to='front_right_pivot'>0 0 0 0 -0 0</pose>
      <parent>front_right_pivot</parent>
      <child>front_right_wheel</child>
      <axis>
        <xyz>0 1 0</xyz>
        <limit>
          <lower>-0.823939</lower>
          <upper>0.823939</upper>
          <effort>10000</effort>
          <velocity>30</velocity>
        </limit>
        <dynamics>
          <damping>0</damping>
          <friction>1</friction>
          <spring_reference>0</spring_reference>
          <spring_stiffness>0</spring_stiffness>
        </dynamics>
      </axis>
    </joint>
    <link name='front_right_wheel'>
      <pose relative_to='front_right_wheel_joint'>0 0 0 0 -0 0</pose>
      <inertial>
        <pose>0 0 0 0 -0 0</pose>
        <mass>2.6357</mass>
        <inertia>
          <ixx>0.0246688</ixx>
          <ixy>0</ixy>
          <ixz>0</ixz>
          <iyy>0.0246688</iyy>
          <iyz>0</iyz>
          <izz>0.0441058</izz>
        </inertia>
      </inertial>
      <collision name='front_right_wheel_collision_collision'>
        <pose>0 0 0 -1.5707 0 0</pose>
        <geometry>
          <cylinder>
            <length>0.1143</length>
            <radius>0.17775</radius>
          </cylinder>
        </geometry>
        <surface>
          <contact>
            <ode/>
          </contact>
          <friction>
            <ode>
              <mu>0.5</mu>
              <mu2>10</mu2>
            </ode>
          </friction>
        </surface>
      </collision>
      <visual name='front_right_wheel_visual'>
        <pose>0 0 0 -3.14159 0 0</pose>
        <geometry>
          <mesh>
            <scale>1 1 1</scale>
            <uri>file://$(find pod2_description)/meshes/wheel.stl</uri>
          </mesh>
        </geometry>
        <material>
          <script>
            <name>Gazebo/Black</name>
            <uri>file://media/materials/scripts/gazebo.material</uri>
          </script>
        </material>
      </visual>
      <slip1 value='0.01'/>
      <slip2 value='0.001'/>
    </link>
    <plugin name='ackermann_drive' filename='libgazebo_ros_ackermann_drive.so'>
      <ros>
        <namespace>podcar</namespace>
        <remapping>cmd_vel:=cmd_vel</remapping>
        <remapping>odom:=odom</remapping>
        <remapping>distance:=distance</remapping>
      </ros>
      <update_rate>100.0</update_rate>
      <front_left_joint>front_left_wheel_joint</front_left_joint>
      <front_right_joint>front_right_wheel_joint</front_right_joint>
      <rear_left_joint>back_left_wheel_joint</rear_left_joint>
      <rear_right_joint>back_right_wheel_joint</rear_right_joint>
      <left_steering_joint>tracking_left_pivot_joint</left_steering_joint>
      <right_steering_joint>tracking_right_pivot_joint</right_steering_joint>
      <steering_wheel_joint>trackingrod_joint</steering_wheel_joint>
      <max_steer>0.85</max_steer>
      <max_steering_angle>7.85</max_steering_angle>
      <max_speed>22</max_speed>
      <left_steering_pid_gain>4000 0 1</left_steering_pid_gain>
      <left_steering_i_range>0 0</left_steering_i_range>
      <right_steering_pid_gain>4000 0 1</right_steering_pid_gain>
      <right_steering_i_range>0 0</right_steering_i_range>
      <linear_velocity_pid_gain>4000 0 1</linear_velocity_pid_gain>
      <linear_velocity_i_range>0 0</linear_velocity_i_range>
      <publish_odom>1</publish_odom>
      <publish_odom_tf>1</publish_odom_tf>
      <publish_wheel_tf>1</publish_wheel_tf>
      <publish_distance>1</publish_distance>
      <odometry_frame>odom</odometry_frame>
      <robot_base_frame>base_link</robot_base_frame>
    </plugin>
    <static>0</static>
    <plugin name='gazebo_joint_state_publisher' filename='libgazebo_ros_joint_state_publisher.so'>
      <robotNamespace>/podcar</robotNamespace>
      <joint_name>trackingrod_joint</joint_name>
      <joint_name>tracking_left_pivot_joint</joint_name>
      <joint_name>tracking_right_pivot_joint</joint_name>
      <joint_name>velodyne_base_mount_joint</joint_name>
      <joint_name>velodyne_base_scan_joint</joint_name>
      <joint_name>front_left_wheel_joint</joint_name>
      <joint_name>front_right_wheel_joint</joint_name>
      <joint_name>back_left_wheel_joint</joint_name>
      <joint_name>back_right_wheel_joint</joint_name>
      <updateRate>100.0</updateRate>
      <alwaysOn>1</alwaysOn>
    </plugin>
    <pose>0 0 0.3 0 -0 0</pose>
  </model>
</sdf>

