<?xml version="1.0" ?>
<!-- =================================================================================== -->
<!-- |    This document was autogenerated by xacro from podcar.urdf.xacro              | -->
<!-- |    EDITING THIS FILE BY HAND IS NOT RECOMMENDED                                 | -->
<!-- =================================================================================== -->
<robot name="podcar" xmlns:controller="http://playerstage.sourceforge.net/gazebo/xmlschema/#controller" xmlns:interface="http://playerstage.sourceforge.net/gazebo/xmlschema/#interface">
  <gazebo reference="base_link">
    <material>Gazebo/Blue</material>
  </gazebo>
  <gazebo reference="front_left_wheel">
    <mu1 value="0.95"/>
    <mu2 value="0.95"/>
    <minDepth>0.005</minDepth>
    <kp>1e8</kp>
    <material>Gazebo/Black</material>
  </gazebo>
  <gazebo reference="front_right_wheel">
    <mu1 value="0.95"/>
    <mu2 value="0.95"/>
    <minDepth>0.005</minDepth>
    <kp>1e8</kp>
    <material>Gazebo/Black</material>
  </gazebo>
  <gazebo reference="back_left_wheel">
    <mu1 value="0.95"/>
    <mu2 value="0.95"/>
    <minDepth>0.005</minDepth>
    <kp>1e8</kp>
    <material>Gazebo/Black</material>
  </gazebo>
  <gazebo reference="back_right_wheel">
    <mu1 value="0.95"/>
    <mu2 value="0.95"/>
    <minDepth>0.005</minDepth>
    <kp>1e8</kp>
    <material>Gazebo/Black</material>
  </gazebo> 
  <link name="front_left_wheel">
    <origin xyz="0.6 0.285475 0.0" rpy="0 0 0"/>
    <inertial>
      <mass value="2.6357"/>
      <origin xyz="0 0 0"/>
      <inertia ixx="0.0246688" ixy="0.0" ixz="0.0" iyy="0.0246688" iyz="0.0" izz="0.0441058"/>
    </inertial>
    <collision name="front_left_wheel_collision">
      <origin xyz="0 0 0" rpy="-1.5707 0 0"/>
      <geometry>
        <cylinder length="0.1143" radius="0.17775"/>
      </geometry>
    </collision>
    <visual>
      <origin xyz="0 0 0" rpy="-3.14159 0 0"/>
      <geometry>
        <mesh filename="package://pod2_description/meshes/wheel.stl"/>
      </geometry>
      
    </visual>
  </link>
  <link name="front_right_wheel">
    <origin xyz="0.6 -0.285475 0.0" rpy="0 0 0"/>
    <inertial>
      <mass value="2.6357"/>
      <origin xyz="0 0 0"/>
      <inertia ixx="0.0246688" ixy="0.0" ixz="0.0" iyy="0.0246688" iyz="0.0" izz="0.0441058"/>
    </inertial>
    <collision name="front_right_wheel_collision">
      <origin xyz="0 0 0" rpy="-1.5707 0 0"/>
      <geometry>
        <cylinder length="0.1143" radius="0.17775"/>
      </geometry>
    </collision>
    <visual>
      <origin xyz="0 0 0" rpy="-3.14159 0 0"/>
      <geometry>
        <mesh filename="package://pod2_description/meshes/wheel.stl"/>
      </geometry> 
    </visual>
  </link>
  <link name="back_left_wheel">
    <origin xyz="-0.6 0.285475 0.0" rpy="0 0 0"/>
    <inertial>
      <mass value="2.6357"/>
      <origin xyz="0 0 0"/>
      <inertia ixx="0.0246688" ixy="0.0" ixz="0.0" iyy="0.0246688" iyz="0.0" izz="0.0441058"/>
    </inertial>
    <collision name="back_left_wheel_collision">
      <origin xyz="0 0 0" rpy="-1.5707 0 0"/>
      <geometry>
        <cylinder length="0.1143" radius="0.17775"/>
      </geometry>
    </collision>
    <visual>
      <origin xyz="0 0 0" rpy="-3.14159 0 0"/>
      <geometry>
        <mesh filename="package://pod2_description/meshes/wheel.stl"/>
      </geometry> 
    </visual>
  </link>
  <link name="back_right_wheel">
    <origin xyz="-0.6 -0.285475 0.0" rpy="0 0 0"/>
    <inertial>
      <mass value="2.6357"/>
      <origin xyz="0 0 0" rpy="0 0 0"/>
      <inertia ixx="0.0246688" ixy="0.0" ixz="0.0" iyy="0.0246688" iyz="0.0" izz="0.0441058"/>
    </inertial>
    <collision name="back_right_wheel_collision">
      <origin xyz="0 0 0" rpy="-1.5707 0 0"/>
      <geometry>
        <cylinder length="0.1143" radius="0.17775"/>
      </geometry>
    </collision>
    <visual>
      <origin xyz="0 0 0" rpy="-3.14159 0 0"/>
      <geometry>
        <mesh filename="package://pod2_description/meshes/wheel.stl"/>
      </geometry> 
    </visual>
  </link>
  <link name="front_left_pivot">
    <origin xyz="0.6 0.285475 0.0" rpy="0 0 0"/>
    <inertial>
      <mass value="2.6357"/>
      <origin xyz="0 0 0"/>
      <inertia ixx="0.0246688" ixy="0.0" ixz="0.0" iyy="0.0246688" iyz="0.0" izz="0.0441058"/>
    </inertial>
  </link>
  <link name="front_right_pivot">
    <origin xyz="0.6 -0.285475 0.0" rpy="0 0 0"/>
    <inertial>
      <mass value="2.6357"/>
      <origin xyz="0 0 0"/>
      <inertia ixx="0.0246688" ixy="0.0" ixz="0.0" iyy="0.0246688" iyz="0.0" izz="0.0441058"/>
    </inertial>
  </link> 
  <link name="base_footprint">
    <visual>
      <origin rpy="0 0 0" xyz="0 0 0"/>
      
    </visual>
  </link>
  <joint name="base_link_joint" type="fixed">
    <origin rpy="0 0 0" xyz="0 0 0"/>
    <parent link="base_footprint"/>
    <child link="base_link"/>
  </joint>
  <link name="base_link">
    <inertial>
      <mass value="33.855"/>
      <origin rpy=" 0 0 0" xyz="-0.0856132 -0.000839955 0.238145"/>
      <inertia ixx="2.2343" ixy="-0.023642" ixz="0.275174" iyy="3.42518" iyz="0.00239624" izz="2.1241"/>
    </inertial>
    <collision>
      <origin rpy=" 0 0 0" xyz="0 0 0.25"/>
      <geometry>
        <box size="1.6 0.73 0.1"/>
      </geometry>
    </collision>
    <visual>
      <origin rpy="0 0 1.57079" xyz="0 0 0"/>
      <geometry>
        <mesh filename="package://pod2_description/meshes/podcarv3.dae" scale="1 1 1"/>
        <!-- <scale>65 69 69</scale> -->
      </geometry>
    </visual>
  </link>
  <joint name="back_left_wheel_joint" type="revolute">
    <parent link="base_link"/>
    <child link="back_left_wheel"/>
    <origin rpy="0 0 0" xyz="-0.6 0.4 0"/>
    <axis xyz="0 1 0"/>
    <limit effort="500000" lower="-0.785398" upper="0.785398" velocity="250"/>
  </joint>
  <joint name="back_right_wheel_joint" type="revolute">
    <parent link="base_link"/>
    <child link="back_right_wheel"/>
    <origin rpy="0 0 0" xyz="-0.6 -0.4 0"/>
    <axis xyz="0 1 0"/>
    <limit effort="500000" lower="-0.785398" upper="0.785398" velocity="250"/>
  </joint>
  <joint name="front_left_pivot_joint" type="revolute">
    <parent link="base_link"/>
    <child link="front_left_pivot"/>
    <origin rpy="0 0 0" xyz="0.6 0.4 0"/>
    <axis xyz="0 0 1"/>
    <limit effort="500000" lower="-0.785398" upper="0.785398" velocity="250"/>
  </joint>
  <joint name="front_left_wheel_joint" type="revolute">
    <parent link="front_left_pivot"/>
    <child link="front_left_wheel"/>
    <origin rpy="0 0 0" xyz="0 0 0"/>
    <axis xyz="0 1 0"/>
    <limit effort="500000" lower="-0.785398" upper="0.785398" velocity="250"/>
  </joint>
  <joint name="front_right_pivot_joint" type="revolute">
    <parent link="base_link"/>
    <child link="front_right_pivot"/>
    <origin rpy="0 0 0" xyz="0.6 -0.4 0"/>
    <axis xyz="0 0 1"/>
    <limit effort="500000" lower="-0.785398" upper="0.785398" velocity="250"/>
  </joint>
  <joint name="front_right_wheel_joint" type="revolute">
    <parent link="front_right_pivot"/>
    <child link="front_right_wheel"/>
    <origin rpy="0 0 0" xyz="0 0 0"/>
    <axis xyz="0 1 0"/>
    <limit effort="500000" lower="-0.785398" upper="0.785398" velocity="250"/>
  </joint>
  <joint name="trackingrod_joint" type="fixed">
    <origin rpy="0.0 0 0" xyz="0.6 0 0"/>
    <parent link="base_link"/>
    <child link="trackingrod"/>
  </joint>
  <link name="trackingrod">
    <origin xyz="0.5 0 0.0" rpy="0 0 0"/>
    <inertial>
      <mass value="2.6357"/>
      <origin xyz="0 0 0"/>
      <inertia ixx="0.0246688" ixy="0.0" ixz="0.0" iyy="0.0246688" iyz="0.0" izz="0.0441058"/>
    </inertial>
    <visual name="trackingrod_visual">
      <origin xyz="0 0 0" rpy="0 0 0 "/>
      <geometry>
        <box size="0.1 0.7 0.1"/>
      </geometry>
    </visual>
  </link>
  <joint name="tracking_left_pivot_joint" type="revolute">
    <parent link="trackingrod"/>
    <child link="front_left_pivot"/>
    <origin rpy="0 0 0.0" xyz="0 0.4 0"/>
    <axis xyz="0 0 1"/>
    <limit effort="500000" lower="-0.785398" upper="0.785398" velocity="250"/>
  </joint>
  <joint name="tracking_right_pivot_joint" type="revolute">
    <parent link="trackingrod"/>
    <child link="front_right_pivot"/>
    <origin rpy="0 0 0.0" xyz="0 -0.4 0"/>
    <axis xyz="0 0 1"/>
    <limit effort="500000" lower="-0.785398" upper="0.785398" velocity="250"/>
  </joint>
  
  
  <gazebo>
    <plugin filename="libgazebo_ros_joint_state_publisher.so" name="joint_state_publisher">
      <robotNamespace>/podcar</robotNamespace>
      <jointName>trackingrod_joint, tracking_left_pivot_joint, tracking_right_pivot_joint, front_left_wheel_joint, front_right_wheel_joint, front_left_pivot_joint, front_right_pivot_joint, back_left_wheel_joint, back_right_wheel_joint</jointName>
      <updateRate>100.0</updateRate>
      <alwaysOn>true</alwaysOn>
    </plugin>
  </gazebo>
</robot>

